<?xml version="1.0" encoding="utf-8"?>
<robot name="rex" xmlns:xacro="http://www.ros.org/wiki/xacro">
  <material name="yellow">
    <color rgba="0.92 0.83 0.0 1"/>
  </material>
  <material name="black">
    <color rgba="0.1 0.1 0.1 1"/>
  </material>
  <material name="grey">
    <color rgba="0.6 0.6 0.6 1"/>
  </material>
  <!-- Params -->
  <!-- Macros -->
  <!-- Robot Body -->
  <link name="base_link">
    <contact>
      <lateral_friction value="1"/>
    </contact>
    <visual>
      <geometry>
        <mesh filename="stl/mainbody.stl" scale="0.001 0.001 0.001"/>
      </geometry>
      <material name="black"/>
      <origin rpy="0 0 0" xyz="0 0 0"/>
    </visual>
    <collision>
      <geometry>
        <mesh filename="stl/mainbody.stl" scale="0.001 0.001 0.001"/>
      </geometry>
      <origin rpy="0 0 0" xyz="0 0 0"/>
    </collision>
    <inertial>
      <mass value="12"/>
      <inertia ixx="0.22" ixy="0" ixz="0" iyy="0.431" iyz="0" izz="0.565"/>
    </inertial>
  </link>

 <!-- Lidar Backpack
  <link name="lidar_link">
   <visual>
     <geometry>
       <mesh filename="stl/rplidar_main.stl" scale="0.001 0.001 0.001"/>
     </geometry>
     <material name="black"/>
     <origin rpy="1.57075 0 0" xyz="-0.06425 0.02885 0"/>
   </visual>
   <collision>
     <geometry>
       <box size="0.0985 0.0577 0.07"/>
     </geometry>
     <origin rpy="0 0 0" xyz="0 0 0"/>
   </collision>
   <inertial>
     <mass value="0.1"/>
     <inertia ixx="100" ixy="0" ixz="0" iyy="100" iyz="0" izz="100"/>
   </inertial>
  </link>
  <joint name="base_lidar" type="fixed">
   <parent link="base_link"/>
   <child link="lidar_link"/>
   <origin xyz="0 0 0.035"/>
  </joint> -->

  <!-- create head & tail -->
  <link name="chassis_front_link">
    <contact>
      <lateral_friction value="1"/>
    </contact>
    <visual>
      <geometry>
        <mesh filename="stl/frontpart.stl" scale="0.001 0.001 0.001"/>
      </geometry>
      <origin rpy="0 0 0" xyz="0 0 0"/>
      <material name="yellow"/>
    </visual>
    <collision>
      <geometry>
        <mesh filename="stl/frontpart.stl" scale="0.001 0.001 0.001"/>
      </geometry>
      <origin rpy="0 0 0" xyz="0 0 0"/>
    </collision>
    <inertial>
      <mass value="0.5"/>
      <inertia ixx="0.22" ixy="0" ixz="0" iyy="0.431" iyz="0" izz="0.565"/>
    </inertial>
  </link>

  <joint name="chassis_base_front" type="fixed">
    <parent link="base_link"/>
    <child link="chassis_front_link"/>
    <origin rpy="0 0 0" xyz="-0.042 -0.055 -0.01"/>
  </joint>

  <link name="chassis_rear_link">
    <contact>
      <lateral_friction value="1"/>
    </contact>
    <visual>
      <geometry>
        <mesh filename="stl/backpart.stl" scale="0.001 0.001 0.001"/>
      </geometry>
      <origin rpy="0 0 0" xyz="0 0 0"/>
      <material name="yellow"/>
    </visual>
    <collision>
      <geometry>
        <mesh filename="stl/backpart.stl" scale="0.001 0.001 0.001"/>
      </geometry>
      <origin rpy="0 0 0" xyz="0 0 0"/>
    </collision>
    <inertial>
      <mass value="0.5"/>
      <inertia ixx="0.22" ixy="0" ixz="0" iyy="0.431" iyz="0" izz="0.565"/>
    </inertial>
  </link>

  <joint name="chassis_base_rear" type="fixed">
    <parent link="base_link"/>
    <child link="chassis_rear_link"/>
    <origin rpy="0 0 0" xyz="0.05 0 -0.038"/>
  </joint>

  <!-- Front Left Leg -->
  <link name="front_left_shoulder_link">
    <contact>
      <lateral_friction value="1"/>
    </contact>
    <visual>
      <geometry>
        <mesh filename="stl/shoulder.stl" scale="0.001 0.001 0.001"/>
      </geometry>
      <origin rpy="0 0 0" xyz="0 0 0"/>
      <material name="black"/>
    </visual>
    <collision>
      <geometry>
        <mesh filename="stl/shoulder.stl" scale="0.001 0.001 0.001"/>
      </geometry>
      <origin rpy="0 0 0" xyz="0 0 0"/>
    </collision>
    <inertial>
      <mass value="1"/>
      <inertia ixx="0.002" ixy="0" ixz="0" iyy=".002" iyz="0" izz=".001"/>
    </inertial>
  </link>

  <joint name="motor_front_left_shoulder" type="revolute">
    <parent link="base_link"/>
    <child link="front_left_shoulder_link"/>
    <axis xyz="1 0 0"/>
    <origin rpy="0 0 0" xyz="-0.095 -0.035 0"/>
    <limit effort="100.0" lower="-1.0" upper="1.0" velocity="100"/>
    <dynamics damping="0.0" friction="0.0"/>
  </joint>

  <link name="front_left_leg_link">
    <contact>
      <lateral_friction value="1"/>
    </contact>
    <visual>
      <geometry>
        <mesh filename="stl/upper_leg.stl" scale="0.001 0.001 0.001"/>
      </geometry>
      <origin rpy="0 0 -1.57" xyz="0 0 0"/>
      <material name="yellow"/>
    </visual>
    <collision>
      <geometry>
        <mesh filename="stl/upper_leg.stl" scale="0.001 0.001 0.001"/>
      </geometry>
      <origin rpy="0 0 -1.57" xyz="0 0 0"/>
    </collision>
    <inertial>
      <mass value="1.5"/>
       <inertia ixx="0.015" ixy="0" ixz="0" iyy="0.007" iyz="0" izz="0.01"/>
    </inertial>
  </link>

  <joint name="motor_front_left_leg" type="revolute">
    <parent link="front_left_shoulder_link"/>
    <child link="front_left_leg_link"/>
    <axis xyz="0 1 0"/>
    <origin rpy="0 0 0" xyz="0 -0.017 0"/>
    <limit effort="100.0" lower="-1.57" upper="1.57" velocity="100"/>
    <dynamics damping="0.0" friction="0.0"/>
  </joint>

  <link name="front_left_foot_link">
    <contact>
      <lateral_friction value="1"/>
    </contact>
    <visual>
      <geometry>
        <mesh filename="stl/lower_leg_solid.stl" scale="0.001 0.001 0.001"/>
      </geometry>
      <origin rpy="0 0 1.57" xyz="0.0 0.0 0.0"/>
      <material name="black"/>
    </visual>
    <collision>
      <geometry>
        <mesh filename="stl/lower_leg_solid.stl" scale="0.001 0.001 0.001"/>
      </geometry>
      <origin rpy="0 0 1.57" xyz="0.0 0.0 0.0"/>
    </collision>
    <inertial>
      <mass value="0.25"/>
      <inertia ixx="0.002" ixy="0" ixz="0" iyy="0.002" iyz="0" izz="0.002"/>
    </inertial>
  </link>

  <joint name="foot_motor_front_left" type="revolute">
    <parent link="front_left_leg_link"/>
    <child link="front_left_foot_link"/>
    <axis xyz="0 1 0"/>
    <origin rpy="0 0 0" xyz="0 -0.047 -0.16"/>
    <limit effort="100.0" lower="-3.14" upper="3.14" velocity="100"/>
    <dynamics damping="0.0" friction="0.0"/>
  </joint>

  <link name="front_left_toe_link">
     <contact>
      <friction_anchor/>
      <stiffness value="30000.0"/>
      <damping value="1000.0"/>
      <spinning_friction value="0.1"/>
      <lateral_friction value="1.0"/>
    </contact>
    <visual>
      <geometry>
        <mesh filename="stl/foot.stl" scale="0.001 0.001 0.001"/>
      </geometry>
      <origin rpy="0 0 0" xyz="0 0 0"/>
      <material name="grey"/>
    </visual>
    <collision>
      <geometry>
        <mesh filename="stl/foot.stl" scale="0.001 0.001 0.001"/>
      </geometry>
      <origin rpy="0 0 0" xyz="0 0 0"/>
    </collision>
    <inertial>
      <mass value="0.01"/>
      <inertia ixx="0.000025" ixy="0" ixz="0" iyy="0.000025" iyz="0" izz="0.000025"/>
    </inertial>
  </link>

  <joint name="toe_joint_front_left" type="fixed">
    <parent link="front_left_foot_link"/>
    <child link="front_left_toe_link"/>
    <origin xyz="0 -0.0098 -0.16"/>
    <dynamics damping="0.0" friction="0.0"/>
  </joint>

  <!-- Front Right Leg -->
  <link name="front_right_shoulder_link">
    <contact>
      <lateral_friction value="1"/>
    </contact>
    <visual>
      <geometry>
        <mesh filename="stl/shoulder.stl" scale="0.001 0.001 0.001"/>
      </geometry>
      <origin rpy="0 0 3.14" xyz="0 0 0"/>
      <material name="black"/>
    </visual>
    <collision>
      <geometry>
        <mesh filename="stl/shoulder.stl" scale="0.001 0.001 0.001"/>
      </geometry>
      <origin rpy="0 0 3.14" xyz="0 0 0"/>
    </collision>
    <inertial>
      <mass value="1"/>
      <inertia ixx="0.002" ixy="0" ixz="0" iyy=".002" iyz="0" izz=".001"/>
    </inertial>
  </link>

  <joint name="motor_front_right_shoulder" type="revolute">
    <parent link="base_link"/>
    <child link="front_right_shoulder_link"/>
    <axis xyz="1 0 0"/>
    <origin rpy="0 0 0" xyz="-0.095 0.035 0"/>
    <limit effort="100.0" lower="-1.0" upper="1.0" velocity="100"/>
    <dynamics damping="0.0" friction="0.0"/>
  </joint>

  <link name="front_right_leg_link">
    <contact>
      <lateral_friction value="1"/>
    </contact>
    <visual>
      <geometry>
        <mesh filename="stl/upper_leg.stl" scale="0.001 0.001 0.001"/>
      </geometry>
      <origin rpy="0 0 1.57" xyz="0 0 0"/>
      <material name="yellow"/>
    </visual>
    <collision>
      <geometry>
        <mesh filename="stl/upper_leg.stl" scale="0.001 0.001 0.001"/>
      </geometry>
      <origin rpy="0 0 1.57" xyz="0 0 0"/>
    </collision>
    <inertial>
      <mass value="1.5"/>
      <inertia ixx="0.016" ixy="0" ixz="0" iyy="0.007" iyz="0" izz="0.011"/>
    </inertial>
  </link>

  <joint name="motor_front_right_leg" type="revolute">
    <parent link="front_right_shoulder_link"/>
    <child link="front_right_leg_link"/>
    <axis xyz="0 1 0"/>
    <origin rpy="0 0 0" xyz="0 0.017 0"/>
    <limit effort="100.0" lower="-1.57" upper="1.57" velocity="100"/>
    <dynamics damping="0.0" friction="0.0"/>
  </joint>

  <link name="front_right_foot_link">
    <contact>
      <lateral_friction value="1"/>
    </contact>
    <visual>
      <geometry>
        <mesh filename="stl/lower_leg_solid.stl" scale="0.001 0.001 0.001"/>
      </geometry>
      <origin rpy="0 0 -1.57" xyz="0 0 0"/>
      <material name="black"/>
    </visual>
    <collision>
      <geometry>
        <mesh filename="stl/lower_leg_solid.stl" scale="0.001 0.001 0.001"/>
      </geometry>
      <origin rpy="0 0 -1.57" xyz="0 0 0"/>
    </collision>
    <inertial>
      <mass value="0.25"/>
      <inertia ixx="0.002" ixy="0" ixz="0" iyy="0.002" iyz="0" izz="0.002"/>
    </inertial>
  </link>

  <joint name="foot_motor_front_right" type="revolute">
    <parent link="front_right_leg_link"/>
    <child link="front_right_foot_link"/>
    <axis xyz="0 1 0"/>
    <origin rpy="0 0 0" xyz="0 0.047 -0.16"/>
    <limit effort="100.0" lower="-3.14" upper="3.14" velocity="100"/>
    <dynamics damping="0.0" friction="0"/>
  </joint>

  <link name="front_right_toe_link">
     <contact>
      <friction_anchor/>
      <stiffness value="30000.0"/>
      <damping value="1000.0"/>
      <spinning_friction value="0.1"/>
      <lateral_friction value="1.0"/>
    </contact>
    <visual>
      <geometry>
        <mesh filename="stl/foot.stl" scale="0.001 0.001 0.001"/>
      </geometry>
      <origin rpy="0 0 0" xyz="0 0 0"/>
      <material name="grey"/>
    </visual>
    <collision>
      <geometry>
        <mesh filename="stl/foot.stl" scale="0.001 0.001 0.001"/>
      </geometry>
      <origin rpy="0 0 0" xyz="0 0 0"/>
    </collision>
    <inertial>
      <mass value="0.01"/>
      <inertia ixx="0.000025" ixy="0" ixz="0" iyy="0.000025" iyz="0" izz="0.000025"/>
    </inertial>
  </link>

  <joint name="toe_joint_front_right" type="fixed">
    <parent link="front_right_foot_link"/>
    <child link="front_right_toe_link"/>
    <origin xyz="0 -0.0098 -0.16"/>
    <dynamics damping="0.0" friction="0.0"/>
  </joint>

  <!-- Rear Left Leg -->
  <link name="rear_left_shoulder_link">
    <contact>
      <lateral_friction value="1"/>
    </contact>
    <visual>
      <geometry>
        <mesh filename="stl/shoulder.stl" scale="0.001 0.001 0.001"/>
      </geometry>
      <origin rpy="0 0 0" xyz="0 0 0"/>
      <material name="black"/>
    </visual>
    <collision>
      <geometry>
        <mesh filename="stl/shoulder.stl" scale="0.001 0.001 0.001"/>
      </geometry>
      <origin rpy="0 0 0" xyz="0 0 0"/>
    </collision>
    <inertial>
      <mass value="1"/>
      <inertia ixx="0.002" ixy="0" ixz="0" iyy="0.002" iyz="0" izz="0.001"/>
    </inertial>
  </link>

  <joint name="motor_rear_left_shoulder" type="revolute">
    <parent link="base_link"/>
    <child link="rear_left_shoulder_link"/>
    <axis xyz="1 0 0"/>
    <origin rpy="0 0 0" xyz="0.09 -0.035 0"/>
    <limit effort="100.0" lower="-1.0" upper="1.0" velocity="100"/>
    <dynamics damping="0.0" friction="0.0"/>
  </joint>

  <link name="rear_left_leg_link">
    <contact>
      <lateral_friction value="1"/>
    </contact>
    <visual>
      <geometry>
        <mesh filename="stl/upper_leg.stl" scale="0.001 0.001 0.001"/>
      </geometry>
      <origin rpy="0 0 -1.57" xyz="0 0 0"/>
      <material name="yellow"/>
    </visual>
    <collision>
      <geometry>
        <mesh filename="stl/upper_leg.stl" scale="0.001 0.001 0.001"/>
      </geometry>
      <origin rpy="0 0 -1.57" xyz="0 0 0"/>
    </collision>
    <inertial>
      <mass value="1.5"/>
      <inertia ixx="0.016" ixy="0" ixz="0" iyy="0.007" iyz="0" izz="0.011"/>
    </inertial>
  </link>

  <joint name="motor_rear_left_leg" type="revolute">
    <parent link="rear_left_shoulder_link"/>
    <child link="rear_left_leg_link"/>
    <axis xyz="0 1 0"/>
    <origin rpy="0 0 0" xyz="0 -0.017 0"/>
    <limit effort="100.0" lower="-1.57" upper="1.57" velocity="100"/>
    <dynamics damping="0.0" friction="0.0"/>
  </joint>

  <link name="rear_left_foot_link">
    <contact>
      <lateral_friction value="1"/>
    </contact>
    <visual>
      <geometry>
        <mesh filename="stl/lower_leg_solid.stl" scale="0.001 0.001 0.001"/>
      </geometry>
      <origin rpy="0 0 1.57" xyz="0 0 0"/>
      <material name="black"/>
    </visual>
    <collision>
      <geometry>
        <mesh filename="stl/lower_leg_solid.stl" scale="0.001 0.001 0.001"/>
      </geometry>
      <origin rpy="0 0 1.57" xyz="0 0 0"/>
    </collision>
    <inertial>
      <mass value="0.25"/>
      <inertia ixx="0.002" ixy="0" ixz="0" iyy="0.002" iyz="0" izz="0.002"/>
    </inertial>
  </link>

  <joint name="foot_motor_rear_left" type="revolute">
    <parent link="rear_left_leg_link"/>
    <child link="rear_left_foot_link"/>
    <axis xyz="0 1 0"/>
    <origin rpy="0 0 0" xyz="0 -0.047 -0.16"/>
    <limit effort="100.0" lower="-3.14" upper="3.14" velocity="100"/>
    <dynamics damping="0.0" friction="0.0"/>
  </joint>

  <link name="rear_left_toe_link">
     <contact>
      <friction_anchor/>
      <stiffness value="30000.0"/>
      <damping value="1000.0"/>
      <spinning_friction value="0.1"/>
      <lateral_friction value="1.0"/>
    </contact>
    <visual>
      <geometry>
        <mesh filename="stl/foot.stl" scale="0.001 0.001 0.001"/>
      </geometry>
      <origin rpy="0 0 0" xyz="0 0 0"/>
      <material name="grey"/>
    </visual>
    <collision>
      <geometry>
        <mesh filename="stl/foot.stl" scale="0.001 0.001 0.001"/>
      </geometry>
      <origin rpy="0 0 0" xyz="0 0 0"/>
    </collision>
    <inertial>
      <mass value="0.01"/>
      <inertia ixx="0.000025" ixy="0" ixz="0" iyy="0.000025" iyz="0" izz="0.000025"/>
    </inertial>
  </link>

  <joint name="toe_joint_rear_left" type="fixed">
    <parent link="rear_left_foot_link"/>
    <child link="rear_left_toe_link"/>
    <origin xyz="0 -0.0098 -0.16"/>
    <dynamics damping="0.0" friction="0.0"/>
  </joint>

  <!-- Rear Right Leg -->
  <link name="rear_right_shoulder_link">
    <contact>
      <lateral_friction value="1"/>
    </contact>
    <visual>
      <geometry>
        <mesh filename="stl/shoulder.stl" scale="0.001 0.001 0.001"/>
      </geometry>
      <origin rpy="0 0 3.14" xyz="0 0 0"/>
      <material name="black"/>
    </visual>
    <collision>
      <geometry>
        <mesh filename="stl/shoulder.stl" scale="0.001 0.001 0.001"/>
      </geometry>
      <origin rpy="0 0 3.14" xyz="0 0 0"/>
    </collision>
    <inertial>
      <mass value="1"/>
      <inertia ixx="0.002" ixy="0" ixz="0" iyy="0.002" iyz="0" izz="0.001"/>
    </inertial>
  </link>

  <joint name="motor_rear_right_shoulder" type="revolute">
    <parent link="base_link"/>
    <child link="rear_right_shoulder_link"/>
    <axis xyz="1 0 0"/>
    <origin rpy="0 0 0" xyz="0.09 0.035 0"/>
    <limit effort="100.0" lower="-1.0" upper="1.0" velocity="100"/>
    <dynamics damping="0.0" friction="0.0"/>
  </joint>

  <link name="rear_right_leg_link">
    <contact>
      <lateral_friction value="1"/>
    </contact>
    <visual>
      <geometry>
        <mesh filename="stl/upper_leg.stl" scale="0.001 0.001 0.001"/>
      </geometry>
      <origin rpy="0 0 1.57" xyz="0 0 0"/>
      <material name="yellow"/>
    </visual>
    <collision>
      <geometry>
        <mesh filename="stl/upper_leg.stl" scale="0.001 0.001 0.001"/>
      </geometry>
      <origin rpy="0 0 1.57" xyz="0 0 0"/>
    </collision>
    <inertial>
      <mass value="1.5"/>
      <inertia ixx="0.016" ixy="0" ixz="0" iyy="0.007" iyz="0" izz="0.011"/>
    </inertial>
  </link>

  <joint name="motor_rear_right_leg" type="revolute">
    <parent link="rear_right_shoulder_link"/>
    <child link="rear_right_leg_link"/>
    <axis xyz="0 1 0"/>
    <origin rpy="0 0 0" xyz="0 0.017 0"/>
    <limit effort="100.0" lower="-1.57" upper="1.57" velocity="100"/>
    <dynamics damping="0.0" friction="0.0"/>
  </joint>

  <link name="rear_right_foot_link">
    <contact>
      <lateral_friction value="1"/>
    </contact>
    <visual>
      <geometry>
        <mesh filename="stl/lower_leg_solid.stl" scale="0.001 0.001 0.001"/>
      </geometry>
      <origin rpy="0 0 -1.57" xyz="0 0 0"/>
      <material name="black"/>
    </visual>
    <collision>
      <geometry>
        <mesh filename="stl/lower_leg_solid.stl" scale="0.001 0.001 0.001"/>
      </geometry>
      <origin rpy="0 0 -1.57" xyz="0 0 0"/>
    </collision>
    <inertial>
      <mass value="0.25"/>
      <inertia ixx="0.002" ixy="0" ixz="0" iyy="0.002" iyz="0" izz="0.002"/>
    </inertial>
  </link>

  <joint name="foot_motor_rear_right" type="revolute">
    <parent link="rear_right_leg_link"/>
    <child link="rear_right_foot_link"/>
    <axis xyz="0 1 0"/>
    <origin rpy="0 0 0" xyz="0 0.047 -0.16"/>
    <limit effort="100.0" lower="-3.14" upper="3.14" velocity="100"/>
    <dynamics damping="0.0" friction="0.0"/>
  </joint>

  <link name="rear_right_toe_link">
     <contact>
      <friction_anchor/>
      <stiffness value="30000.0"/>
      <damping value="1000.0"/>
      <spinning_friction value="0.1"/>
      <lateral_friction value="1.0"/>
    </contact>
    <visual>
      <geometry>
        <mesh filename="stl/foot.stl" scale="0.001 0.001 0.001"/>
      </geometry>
      <origin rpy="0 0 0" xyz="0 0 0"/>
      <material name="grey"/>
    </visual>
    <collision>
      <geometry>
        <mesh filename="stl/foot.stl" scale="0.001 0.001 0.001"/>
      </geometry>
      <origin rpy="0 0 0" xyz="0 0 0"/>
    </collision>
    <inertial>
      <mass value="0.01"/>
      <inertia ixx="0.000025" ixy="0" ixz="0" iyy="0.000025" iyz="0" izz="0.000025"/>
    </inertial>
  </link>

  <joint name="toe_joint_rear_right" type="fixed">
    <parent link="rear_right_foot_link"/>
    <child link="rear_right_toe_link"/>
    <origin xyz="0 -0.0098 -0.16"/>
    <dynamics damping="0.0" friction="0.0"/>
  </joint>
</robot>